
<robot name="differential_drive_car">

  <!-- Define the base_link of the car -->
  <link name="base_link">
    <visual>
      <!-- Define the geometry of the car -->
      <geometry>
        <box size="0.706 0.576 0.2"/>
      </geometry>
    </visual>
  </link>

  <link name="left_wheel">
    <visual>
      <geometry>
        <cylinder radius="0.1" length="0.05"/>
      </geometry>
    </visual>
  </link>

  <joint name="left_wheel_joint" type="continuous">
    <parent link="base_link"/>
    <child link="left_wheel"/>
    <axis xyz="0 0 1"/>
  </joint>

  <link name="right_wheel">
    <visual>
      <geometry>
        <cylinder radius="0.1" length="0.05"/>
      </geometry>
    </visual>
  </link>

  <joint name="right_wheel_joint" type="continuous">
    <parent link="base_link"/>
    <child link="right_wheel"/>
    <origin xyz="0.199 0.2 0"/>
    <axis xyz="0 0 1"/>
  </joint>

</robot>